<?xml version="1.0"?>
<robot name="car">


    <link name="base_link">
        <visual>
            <geometry>
                <sphere radius="0.5"/>
            </geometry>
            <origin xyz="0 0 0" rpy="0 0 0"/>
        </visual>
    </link>


   <link name="laser">
        <visual>
            <geometry>
                <sphere radius="0.5"/>
            </geometry>
            <origin xyz="0 0 0" rpy="0 0 0"/>
        </visual>
    </link>
  
   <link name="odom">
        <visual>
            <geometry>
                <sphere radius="0.5"/>
            </geometry>
            <origin xyz="0 0 0" rpy="0 0 0"/>
        </visual>
    </link>

   <link name="map">
        
            <origin xyz="0 0 0" rpy="0 0 0"/>
        
   </link>


   <joint name="map_to_odom" type="continuous">
        <parent link="map"/>
        <child link="odom"/>
        <origin xyz="0 0 0" rpy="0 0 0"/>
    </joint>

 


    <joint name="base_link_to_laser" type="fixed">
        <parent link="base_link"/>
        <child link="laser"/>
	<origin xyz="0 0 0" rpy="0 0 0"/>
        <!--origin xyz="0.2 0 0" rpy="3.14 0 0"/-->
    </joint>



    <joint name="base_link_to_map" type="fixed">
        <parent link="base_link"/>
        <child link="map"/>
        <origin xyz="0 0 0"/>
    </joint>
  
</robot>

